Workbook

Sheet Instruções
A1: LEVANTAMENTO AMBIENTAL — FAZENDAS CAMPANELLI
A2: Roteiro de consulta e instrumento de coleta — CAR, Outorgas, Autos de Infração/TCRA, Processos CETESB, Incêndios e Licenciamentos
A4: ATENÇÃO: as abas de dados estão ESTRUTURADAS E PRÉ-PREENCHIDAS com o que consta na planilha de origem (imóvel, município, CCIR, matrícula e área). Os campos ambientais estão EM BRANCO e devem ser preenchidos a partir das consultas oficiais indicadas abaixo — nenhum dado ambiental foi presumido ou estimado.
A6: Item | B6: Órgão / Sistema | C6: Onde consultar (portal) | D6: Dado necessário para a consulta | E6: Documento a obter | F6: Aba de destino
A7: N° do CAR | B7: SICAR / SFB — Consulta Pública | C7: consultapublica.car.gov.br/publico/imoveis/index | D7: N° do recibo do CAR ou CPF/CNPJ do declarante; alternativamente o polígono do imóvel | E7: Demonstrativo do CAR + Recibo de inscrição | F7: CAR
A8: N° do CAR (SP) | B8: SICAR-SP / SIGAM — SEMIL-SP | C8: sigam.ambiente.sp.gov.br • car.sp.gov.br | D8: CPF/CNPJ do proprietário ou n° do CAR | E8: Situação da inscrição, análise e adesão ao PRA | F8: CAR
A9: Outorga (águas estaduais) | B9: DAEE-SP | C9: outorga.daee.sp.gov.br • aplicacoes.daee.sp.gov.br | D9: CPF/CNPJ do requerente ou n° do processo/portaria DAEE | E9: Portaria de outorga / Licença de execução / Dispensa | F9: Outorgas
A10: Outorga (águas federais) | B10: ANA — REGLA / SNIRH | C10: gov.br/ana • snirh.gov.br | D10: CPF/CNPJ ou n° da resolução. Aplica-se a captações no Rio Grande, Paranapanema e Paraná (rios de domínio da União) | E10: Resolução de outorga ANA | F10: Outorgas
A11: Poços tubulares | B11: DAEE / SIAGAS-CPRM | C11: siagasweb.sgb.gov.br | D11: Município + coordenadas do poço | E11: Cadastro do poço e outorga de perfuração/uso | F11: Outorgas
A12: Autos de Infração (estadual) | B12: CETESB / Polícia Militar Ambiental | C12: Agência Ambiental da CETESB do município • cetesb.sp.gov.br | D12: CPF/CNPJ do autuado e/ou n° do auto (AIA/AIPI) | E12: Auto de Infração, Auto de Imposição de Penalidade, extrato de débito | F12: Autos e TCRA
A13: Autos de Infração (federal) | B13: IBAMA — Consulta de autuações | C13: servicos.ibama.gov.br • Painel de Autos de Infração (dadosabertos.ibama.gov.br) | D13: CPF/CNPJ do autuado | E13: Auto de infração e situação do débito/embargo | F13: Autos e TCRA
A14: TCRA / TAC | B14: CETESB / SEMIL-SP / Ministério Público | C14: Agência Ambiental da CETESB • MPSP (comarca do imóvel) | D14: N° do processo administrativo ou CPF/CNPJ | E14: Termo de Compromisso de Recuperação Ambiental e PRAD vinculado | F14: Autos e TCRA
A15: Processo CETESB | B15: CETESB — Agência Ambiental | C15: e-ambiente / SIGAM • protocolo na Agência Ambiental | D15: N° do processo ou CPF/CNPJ do interessado | E15: Extrato/andamento do processo administrativo | F15: Processos CETESB
A16: Incêndios / queimadas | B16: INPE — Programa Queimadas (BDQueimadas) | C16: terrabrasilis.dpi.inpe.br/queimadas • queimadas.dgi.inpe.br | D16: Polígono do imóvel (shapefile do CAR) ou município + período | E16: Relatório de focos de calor e área queimada por data | F16: Incêndios
A17: Incêndios — ocorrência | B17: Corpo de Bombeiros / Defesa Civil / PM Ambiental | C17: Unidade da comarca do imóvel | D17: Data e local da ocorrência | E17: Boletim de Ocorrência e eventual auto de infração vinculado | F17: Incêndios
... A20: Licença de uso de irrigação | B20: CATI/SAA-SP e CETESB | C20: Conforme o porte e a atividade do empreendimento | D20: Descrição da atividade e área irrigada | E20: Licença ou declaração de dispensa | F20: Licenciamentos
A22: CAMINHO MAIS CURTO: a maior parte das consultas acima é feita por CPF/CNPJ do proprietário. Levantando por CNPJ (SICAR, DAEE, IBAMA, CETESB) obtém-se de uma só vez a lista completa de registros do grupo, que depois é rateada por imóvel nas abas deste arquivo.
A24: MUNICÍPIOS DO PORTFÓLIO — REFERÊNCIA PARA PROTOCOLO (confirmar em cetesb.sp.gov.br/agencias-ambientais)
A25: Município | B25: Imóveis | C25: Agência Ambiental CETESB (a confirmar) | D25: UGRHI / Bacia (a confirmar)
A26: Altair | B26: Fazenda Alvorada, Fazenda Santa Rosa, Fazenda São Pedro
A27: Colina | B27: Fazenda São Geraldo, Fazenda Santa Inacia, Fazenda Iracema
A28: Guapiaçu | B28: Fazenda Santo Antonio
A29: Guaraci | B29: Fazenda São João, Fazenda São Francisco (S.Pedro) GEO c/ desmembramento
A30: Monte Azul Paulista | B30: Fazenda Santa Maria
A31: Onda Verde | B31: Fazenda Santa Cruz
A32: Santo Antonio do Aracanguá | B32: Fazenda Conquista, Fazenda Vitória, Fazenda Santa Helena, Fazenda Primavera
A33: Severínia | B33: Fazenda São José, Fazenda São Luiz, Sítio São José I
A34: Sto Antonio do Aracanguá | B34: Fazenda Ipê
A35: Teodoro Sampaio | B35: Fazenda Lago Azul

Sheet Resumo por Imóvel
A1: Imóvel | B1: Município | C1: Tipo | D1: CCIR | E1: Matrículas | F1: Área Mat. (ha) | G1: Área Imóvel (ha) | H1: N° do CAR (principal) | I1: Situação do CAR | J1: Outorgas (qtd) | K1: Autos de Infração (qtd) | L1: TCRA / TAC (qtd) | M1: Processos CETESB (qtd) | N1: Incêndios (qtd) | O1: Licenciamentos (qtd) | P1: Status do levantamento | Q1: Responsável | R1: Data da consulta | S1: Observações
A2: Fazenda Ipê | B2: Sto Antonio do Aracanguá | C2: Própria | D2: 607.029.001.147-7 | E2: 5787 | F2: 473.34 | G2: 473.34 | J2: =COUNTIF(Outorgas!$A:$A,$A2) | K2: =COUNTIFS('Autos e TCRA'!$A:$A,$A2,'Autos e TCRA'!$D:$D,"Auto de Infração*")+COUNTIFS('Autos e TCRA'!$A:$A,$A2,'Autos e TCRA'!$D:$D,"Auto de Imposição*") | L2: =COUNTIFS('Autos e TCRA'!$A:$A,$A2,'Autos e TCRA'!$D:$D,"TCRA")+COUNTIFS('Autos e TCRA'!$A:$A,$A2,'Autos e TCRA'!$D:$D,"TAC") | M2: =COUNTIF('Processos CETESB'!$A:$A,$A2) | N2: =COUNTIF(Incêndios!$A:$A,$A2) | O2: =COUNTIF(Licenciamentos!$A:$A,$A2) | P2: Não iniciado
A3: Fazenda São Geraldo | B3: Colina | C3: Própria | D3: 604.020.000.698-8 | E3: 176, 19852, 14036 | F3: 534.3602 | G3: 534.3602 | J3: =COUNTIF(Outorgas!$A:$A,$A3) | K3: =COUNTIFS('Autos e TCRA'!$A:$A,$A3,'Autos e TCRA'!$D:$D,"Auto de Infração*")+COUNTIFS('Autos e TCRA'!$A:$A,$A3,'Autos e TCRA'!$D:$D,"Auto de Imposição*") | L3: =COUNTIFS('Autos e TCRA'!$A:$A,$A3,'Autos e TCRA'!$D:$D,"TCRA")+COUNTIFS('Autos e TCRA'!$A:$A,$A3,'Autos e TCRA'!$D:$D,"TAC") | M3: =COUNTIF('Processos CETESB'!$A:$A,$A3) | N3: =COUNTIF(Incêndios!$A:$A,$A3) | O3: =COUNTIF(Licenciamentos!$A:$A,$A3) | P3: Não iniciado
A4: Fazenda Conquista | B4: Santo Antonio do Aracanguá | C4: Própria | D4: 607.029.011.673-2 | E4: 73291, 696, 41325, 41326, 41327 | F4: 1136.7708 | G4: 1136.7708 | J4: =COUNTIF(Outorgas!$A:$A,$A4) | K4: =COUNTIFS('Autos e TCRA'!$A:$A,$A4,'Autos e TCRA'!$D:$D,"Auto de Infração*")+COUNTIFS('Autos e TCRA'!$A:$A,$A4,'Autos e TCRA'!$D:$D,"Auto de Imposição*") | L4: =COUNTIFS('Autos e TCRA'!$A:$A,$A4,'Autos e TCRA'!$D:$D,"TCRA")+COUNTIFS('Autos e TCRA'!$A:$A,$A4,'Autos e TCRA'!$D:$D,"TAC") | M4: =COUNTIF('Processos CETESB'!$A:$A,$A4) | N4: =COUNTIF(Incêndios!$A:$A,$A4) | O4: =COUNTIF(Licenciamentos!$A:$A,$A4) | P4: Não iniciado
A5: Fazenda Santo Antonio | B5: Guapiaçu | C5: Própria | D5: 610.046.259.063-2 | E5: 38971, 10632 | F5: 2087.6581 | G5: 2087.6581 | J5: =COUNTIF(Outorgas!$A:$A,$A5) | K5: =COUNTIFS('Autos e TCRA'!$A:$A,$A5,'Autos e TCRA'!$D:$D,"Auto de Infração*")+COUNTIFS('Autos e TCRA'!$A:$A,$A5,'Autos e TCRA'!$D:$D,"Auto de Imposição*") | L5: =COUNTIFS('Autos e TCRA'!$A:$A,$A5,'Autos e TCRA'!$D:$D,"TCRA")+COUNTIFS('Autos e TCRA'!$A:$A,$A5,'Autos e TCRA'!$D:$D,"TAC") | M5: =COUNTIF('Processos CETESB'!$A:$A,$A5) | N5: =COUNTIF(Incêndios!$A:$A,$A5) | O5: =COUNTIF(Licenciamentos!$A:$A,$A5) | P5: Não iniciado
A6: Fazenda Alvorada | B6: Altair | C6: Própria | D6: 603.015.001.104-1 | E6: 7430, 44121, 44122, 44123, 44124 | F6: 679.2288 | G6: 679.2288 | J6: =COUNTIF(Outorgas!$A:$A,$A6) | K6: =COUNTIFS('Autos e TCRA'!$A:$A,$A6,'Autos e TCRA'!$D:$D,"Auto de Infração*")+COUNTIFS('Autos e TCRA'!$A:$A,$A6,'Autos e TCRA'!$D:$D,"Auto de Imposição*") | L6: =COUNTIFS('Autos e TCRA'!$A:$A,$A6,'Autos e TCRA'!$D:$D,"TCRA")+COUNTIFS('Autos e TCRA'!$A:$A,$A6,'Autos e TCRA'!$D:$D,"TAC") | M6: =COUNTIF('Processos CETESB'!$A:$A,$A6) | N6: =COUNTIF(Incêndios!$A:$A,$A6) | O6: =COUNTIF(Licenciamentos!$A:$A,$A6) | P6: Não iniciado
A7: Fazenda Santa Inacia | B7: Colina | C7: Própria | D7: 604.020.001.457-3 | E7: 14892 | F7: 522.5 | G7: 522.5 | J7: =COUNTIF(Outorgas!$A:$A,$A7) | K7: =COUNTIFS('Autos e TCRA'!$A:$A,$A7,'Autos e TCRA'!$D:$D,"Auto de Infração*")+COUNTIFS('Autos e TCRA'!$A:$A,$A7,'Autos e TCRA'!$D:$D,"Auto de Imposição*") | L7: =COUNTIFS('Autos e TCRA'!$A:$A,$A7,'Autos e TCRA'!$D:$D,"TCRA")+COUNTIFS('Autos e TCRA'!$A:$A,$A7,'Autos e TCRA'!$D:$D,"TAC") | M7: =COUNTIF('Processos CETESB'!$A:$A,$A7) | N7: =COUNTIF(Incêndios!$A:$A,$A7) | O7: =COUNTIF(Licenciamentos!$A:$A,$A7) | P7: Não iniciado
A8: Fazenda Iracema | B8: Colina | C8: Própria | D8: 604.020.001.449-2 | E8: 10319 | F8: 550.99 | G8: 550.99 | J8: =COUNTIF(Outorgas!$A:$A,$A8) | K8: =COUNTIFS('Autos e TCRA'!$A:$A,$A8,'Autos e TCRA'!$D:$D,"Auto de Infração*")+COUNTIFS('Autos e TCRA'!$A:$A,$A8,'Autos e TCRA'!$D:$D,"Auto de Imposição*") | L8: =COUNTIFS('Autos e TCRA'!$A:$A,$A8,'Autos e TCRA'!$D:$D,"TCRA")+COUNTIFS('Autos e TCRA'!$A:$A,$A8,'Autos e TCRA'!$D:$D,"TAC") | M8: =COUNTIF('Processos CETESB'!$A:$A,$A8) | N8: =COUNTIF(Incêndios!$A:$A,$A8) | O8: =COUNTIF(Licenciamentos!$A:$A,$A8) | P8: Não iniciado
A9: Fazenda Vitória | B9: Santo Antonio do Aracanguá | C9: Própria | D9: 999.989.600.148-5 | E9: 45933, 45932, 49159, 3201 | F9: 386.0636 | G9: 386.0636 | J9: =COUNTIF(Outorgas!$A:$A,$A9) | K9: =COUNTIFS('Autos e TCRA'!$A:$A,$A9,'Autos e TCRA'!$D:$D,"Auto de Infração*")+COUNTIFS('Autos e TCRA'!$A:$A,$A9,'Autos e TCRA'!$D:$D,"Auto de Imposição*") | L9: =COUNTIFS('Autos e TCRA'!$A:$A,$A9,'Autos e TCRA'!$D:$D,"TCRA")+COUNTIFS('Autos e TCRA'!$A:$A,$A9,'Autos e TCRA'!$D:$D,"TAC") | M9: =COUNTIF('Processos CETESB'!$A:$A,$A9) | N9: =COUNTIF(Incêndios!$A:$A,$A9) | O9: =COUNTIF(Licenciamentos!$A:$A,$A9) | P9: Não iniciado
A10: Fazenda Santa Helena | B10: Santo Antonio do Aracanguá | C10: Própria | D10: 617.016.010.375-7 | E10: 37883, 37882 | F10: 338.8 | G10: 338.8 | J10: =COUNTIF(Outorgas!$A:$A,$A10) | K10: =COUNTIFS('Autos e TCRA'!$A:$A,$A10,'Autos e TCRA'!$D:$D,"Auto de Infração*")+COUNTIFS('Autos e TCRA'!$A:$A,$A10,'Autos e TCRA'!$D:$D,"Auto de Imposição*") | L10: =COUNTIFS('Autos e TCRA'!$A:$A,$A10,'Autos e TCRA'!$D:$D,"TCRA")+COUNTIFS('Autos e TCRA'!$A:$A,$A10,'Autos e TCRA'!$D:$D,"TAC") | M10: =COUNTIF('Processos CETESB'!$A:$A,$A10) | N10: =COUNTIF(Incêndios!$A:$A,$A10) | O10: =COUNTIF(Licenciamentos!$A:$A,$A10) | P10: Não iniciado
A11: Fazenda São José | B11: Severínia | C11: Própria | D11: 611.131.001.260-0 | E11: 7207 | F11: 519.332 | G11: 519.332 | J11: =COUNTIF(Outorgas!$A:$A,$A11) | K11: =COUNTIFS('Autos e TCRA'!$A:$A,$A11,'Autos e TCRA'!$D:$D,"Auto de Infração*")+COUNTIFS('Autos e TCRA'!$A:$A,$A11,'Autos e TCRA'!$D:$D,"Auto de Imposição*") | L11: =COUNTIFS('Autos e TCRA'!$A:$A,$A11,'Autos e TCRA'!$D:$D,"TCRA")+COUNTIFS('Autos e TCRA'!$A:$A,$A11,'Autos e TCRA'!$D:$D,"TAC") | M11: =COUNTIF('Processos CETESB'!$A:$A,$A11) | N11: =COUNTIF(Incêndios!$A:$A,$A11) | O11: =COUNTIF(Licenciamentos!$A:$A,$A11) | P11: Não iniciado
A12: Fazenda São Luiz | B12: Severínia | C12: Própria | D12: 611.131.000.710-0 | E12: 24047, 30714, 12236, 12237, 6710, 24932 | F12: 612.0772 | G12: 612.0772 | J12: =COUNTIF(Outorgas!$A:$A,$A12) | K12: =COUNTIFS('Autos e TCRA'!$A:$A,$A12,'Autos e TCRA'!$D:$D,"Auto de Infração*")+COUNTIFS('Autos e TCRA'!$A:$A,$A12,'Autos e TCRA'!$D:$D,"Auto de Imposição*") | L12: =COUNTIFS('Autos e TCRA'!$A:$A,$A12,'Autos e TCRA'!$D:$D,"TCRA")+COUNTIFS('Autos e TCRA'!$A:$A,$A12,'Autos e TCRA'!$D:$D,"TAC") | M12: =COUNTIF('Processos CETESB'!$A:$A,$A12) | N12: =COUNTIF(Incêndios!$A:$A,$A12) | O12: =COUNTIF(Licenciamentos!$A:$A,$A12) | P12: Não iniciado
A13: Sítio São José I | B13: Severínia | C13: Própria | D13: 611.131.000.612-0 | E13: 417 | F13: 16.94 | G13: 16.94 | J13: =COUNTIF(Outorgas!$A:$A,$A13) | K13: =COUNTIFS('Autos e TCRA'!$A:$A,$A13,'Autos e TCRA'!$D:$D,"Auto de Infração*")+COUNTIFS('Autos e TCRA'!$A:$A,$A13,'Autos e TCRA'!$D:$D,"Auto de Imposição*") | L13: =COUNTIFS('Autos e TCRA'!$A:$A,$A13,'Autos e TCRA'!$D:$D,"TCRA")+COUNTIFS('Autos e TCRA'!$A:$A,$A13,'Autos e TCRA'!$D:$D,"TAC") | M13: =COUNTIF('Processos CETESB'!$A:$A,$A13) | N13: =COUNTIF(Incêndios!$A:$A,$A13) | O13: =COUNTIF(Licenciamentos!$A:$A,$A13) | P13: Não iniciado
... A21: Fazenda São Francisco (S.Pedro) GEO c/ desmembramento | B21: Guaraci | C21: Própria | D21: 603.023.003.344-5 | E21: 52198, 52199, 52200, 89688, 89691, 89692 | F21: 850.5923 | G21: 850.5923 | J21: =COUNTIF(Outorgas!$A:$A,$A21) | K21: =COUNTIFS('Autos e TCRA'!$A:$A,$A21,'Autos e TCRA'!$D:$D,"Auto de Infração*")+COUNTIFS('Autos e TCRA'!$A:$A,$A21,'Autos e TCRA'!$D:$D,"Auto de Imposição*") | L21: =COUNTIFS('Autos e TCRA'!$A:$A,$A21,'Autos e TCRA'!$D:$D,"TCRA")+COUNTIFS('Autos e TCRA'!$A:$A,$A21,'Autos e TCRA'!$D:$D,"TAC") | M21: =COUNTIF('Processos CETESB'!$A:$A,$A21) | N21: =COUNTIF(Incêndios!$A:$A,$A21) | O21: =COUNTIF(Licenciamentos!$A:$A,$A21) | P21: Não iniciado
A22: FAZENDA CÓRREGO RICO - MFG-18000 | C22: Parceira | D22: 603.015.272.353-7 | E22: 10328 - 14023 | J22: =COUNTIF(Outorgas!$A:$A,$A22) | K22: =COUNTIFS('Autos e TCRA'!$A:$A,$A22,'Autos e TCRA'!$D:$D,"Auto de Infração*")+COUNTIFS('Autos e TCRA'!$A:$A,$A22,'Autos e TCRA'!$D:$D,"Auto de Imposição*") | L22: =COUNTIFS('Autos e TCRA'!$A:$A,$A22,'Autos e TCRA'!$D:$D,"TCRA")+COUNTIFS('Autos e TCRA'!$A:$A,$A22,'Autos e TCRA'!$D:$D,"TAC") | M22: =COUNTIF('Processos CETESB'!$A:$A,$A22) | N22: =COUNTIF(Incêndios!$A:$A,$A22) | O22: =COUNTIF(Licenciamentos!$A:$A,$A22) | P22: Não iniciado
A23: FAZENDA QUATRO IRMÃOS - SOAs-18001 | C23: Parceira | D23: 000.019.292.982-2 | E23: 9477 | J23: =COUNTIF(Outorgas!$A:$A,$A23) | K23: =COUNTIFS('Autos e TCRA'!$A:$A,$A23,'Autos e TCRA'!$D:$D,"Auto de Infração*")+COUNTIFS('Autos e TCRA'!$A:$A,$A23,'Autos e TCRA'!$D:$D,"Auto de Imposição*") | L23: =COUNTIFS('Autos e TCRA'!$A:$A,$A23,'Autos e TCRA'!$D:$D,"TCRA")+COUNTIFS('Autos e TCRA'!$A:$A,$A23,'Autos e TCRA'!$D:$D,"TAC") | M23: =COUNTIF('Processos CETESB'!$A:$A,$A23) | N23: =COUNTIF(Incêndios!$A:$A,$A23) | O23: =COUNTIF(Licenciamentos!$A:$A,$A23) | P23: Não iniciado
A24: FAZ. GIRASSOIS - GAQ-18002 | C24: Parceira | D24: 000.019.292.966-0 | E24: 9481 | J24: =COUNTIF(Outorgas!$A:$A,$A24) | K24: =COUNTIFS('Autos e TCRA'!$A:$A,$A24,'Autos e TCRA'!$D:$D,"Auto de Infração*")+COUNTIFS('Autos e TCRA'!$A:$A,$A24,'Autos e TCRA'!$D:$D,"Auto de Imposição*") | L24: =COUNTIFS('Autos e TCRA'!$A:$A,$A24,'Autos e TCRA'!$D:$D,"TCRA")+COUNTIFS('Autos e TCRA'!$A:$A,$A24,'Autos e TCRA'!$D:$D,"TAC") | M24: =COUNTIF('Processos CETESB'!$A:$A,$A24) | N24: =COUNTIF(Incêndios!$A:$A,$A24) | O24: =COUNTIF(Licenciamentos!$A:$A,$A24) | P24: Não iniciado
A25: FAZ. MANGUE - MQ | C25: Parceira | D25: 603.031.273.058-6 | E25: 10487 | J25: =COUNTIF(Outorgas!$A:$A,$A25) | K25: =COUNTIFS('Autos e TCRA'!$A:$A,$A25,'Autos e TCRA'!$D:$D,"Auto de Infração*")+COUNTIFS('Autos e TCRA'!$A:$A,$A25,'Autos e TCRA'!$D:$D,"Auto de Imposição*") | L25: =COUNTIFS('Autos e TCRA'!$A:$A,$A25,'Autos e TCRA'!$D:$D,"TCRA")+COUNTIFS('Autos e TCRA'!$A:$A,$A25,'Autos e TCRA'!$D:$D,"TAC") | M25: =COUNTIF('Processos CETESB'!$A:$A,$A25) | N25: =COUNTIF(Incêndios!$A:$A,$A25) | O25: =COUNTIF(Licenciamentos!$A:$A,$A25) | P25: Não iniciado
A26: FAZENDA AGUA DOCE PARTE IV - RJP | C26: Parceira | D26: 603.031.000.400-4 | E26: 17035 | J26: =COUNTIF(Outorgas!$A:$A,$A26) | K26: =COUNTIFS('Autos e TCRA'!$A:$A,$A26,'Autos e TCRA'!$D:$D,"Auto de Infração*")+COUNTIFS('Autos e TCRA'!$A:$A,$A26,'Autos e TCRA'!$D:$D,"Auto de Imposição*") | L26: =COUNTIFS('Autos e TCRA'!$A:$A,$A26,'Autos e TCRA'!$D:$D,"TCRA")+COUNTIFS('Autos e TCRA'!$A:$A,$A26,'Autos e TCRA'!$D:$D,"TAC") | M26: =COUNTIF('Processos CETESB'!$A:$A,$A26) | N26: =COUNTIF(Incêndios!$A:$A,$A26) | O26: =COUNTIF(Licenciamentos!$A:$A,$A26) | P26: Não iniciado
A27: FAZENDA AGUA DOCE PARTE II - MAP | C27: Parceira | D27: 999.989.956.007-8 | E27: 17033 | J27: =COUNTIF(Outorgas!$A:$A,$A27) | K27: =COUNTIFS('Autos e TCRA'!$A:$A,$A27,'Autos e TCRA'!$D:$D,"Auto de Infração*")+COUNTIFS('Autos e TCRA'!$A:$A,$A27,'Autos e TCRA'!$D:$D,"Auto de Imposição*") | L27: =COUNTIFS('Autos e TCRA'!$A:$A,$A27,'Autos e TCRA'!$D:$D,"TCRA")+COUNTIFS('Autos e TCRA'!$A:$A,$A27,'Autos e TCRA'!$D:$D,"TAC") | M27: =COUNTIF('Processos CETESB'!$A:$A,$A27) | N27: =COUNTIF(Incêndios!$A:$A,$A27) | O27: =COUNTIF(Licenciamentos!$A:$A,$A27) | P27: Não iniciado
A28: FAZENDA ANTONIO BIANCO - SBA | C28: Parceira | D28: 603.031.273.066-7 | E28: 11391 | J28: =COUNTIF(Outorgas!$A:$A,$A28) | K28: =COUNTIFS('Autos e TCRA'!$A:$A,$A28,'Autos e TCRA'!$D:$D,"Auto de Infração*")+COUNTIFS('Autos e TCRA'!$A:$A,$A28,'Autos e TCRA'!$D:$D,"Auto de Imposição*") | L28: =COUNTIFS('Autos e TCRA'!$A:$A,$A28,'Autos e TCRA'!$D:$D,"TCRA")+COUNTIFS('Autos e TCRA'!$A:$A,$A28,'Autos e TCRA'!$D:$D,"TAC") | M28: =COUNTIF('Processos CETESB'!$A:$A,$A28) | N28: =COUNTIF(Incêndios!$A:$A,$A28) | O28: =COUNTIF(Licenciamentos!$A:$A,$A28) | P28: Não iniciado
A29: FAZ. SANTO INACIO - ILMJA | C29: Parceira | D29: 950.122.860.476-5 | E29: 14022 | J29: =COUNTIF(Outorgas!$A:$A,$A29) | K29: =COUNTIFS('Autos e TCRA'!$A:$A,$A29,'Autos e TCRA'!$D:$D,"Auto de Infração*")+COUNTIFS('Autos e TCRA'!$A:$A,$A29,'Autos e TCRA'!$D:$D,"Auto de Imposição*") | L29: =COUNTIFS('Autos e TCRA'!$A:$A,$A29,'Autos e TCRA'!$D:$D,"TCRA")+COUNTIFS('Autos e TCRA'!$A:$A,$A29,'Autos e TCRA'!$D:$D,"TAC") | M29: =COUNTIF('Processos CETESB'!$A:$A,$A29) | N29: =COUNTIF(Incêndios!$A:$A,$A29) | O29: =COUNTIF(Licenciamentos!$A:$A,$A29) | P29: Não iniciado
A30: FAZENDA CÓRREGO RICO - LAN | C30: Parceira | D30: 623.024.006.955-2 | E30: 14021 | J30: =COUNTIF(Outorgas!$A:$A,$A30) | K30: =COUNTIFS('Autos e TCRA'!$A:$A,$A30,'Autos e TCRA'!$D:$D,"Auto de Infração*")+COUNTIFS('Autos e TCRA'!$A:$A,$A30,'Autos e TCRA'!$D:$D,"Auto de Imposição*") | L30: =COUNTIFS('Autos e TCRA'!$A:$A,$A30,'Autos e TCRA'!$D:$D,"TCRA")+COUNTIFS('Autos e TCRA'!$A:$A,$A30,'Autos e TCRA'!$D:$D,"TAC") | M30: =COUNTIF('Processos CETESB'!$A:$A,$A30) | N30: =COUNTIF(Incêndios!$A:$A,$A30) | O30: =COUNTIF(Licenciamentos!$A:$A,$A30) | P30: Não iniciado
A31: FAZENDA OLIVEIRA - MAO | C31: Parceira | D31: 603.031.000.507-8 | E31: 17864 | J31: =COUNTIF(Outorgas!$A:$A,$A31) | K31: =COUNTIFS('Autos e TCRA'!$A:$A,$A31,'Autos e TCRA'!$D:$D,"Auto de Infração*")+COUNTIFS('Autos e TCRA'!$A:$A,$A31,'Autos e TCRA'!$D:$D,"Auto de Imposição*") | L31: =COUNTIFS('Autos e TCRA'!$A:$A,$A31,'Autos e TCRA'!$D:$D,"TCRA")+COUNTIFS('Autos e TCRA'!$A:$A,$A31,'Autos e TCRA'!$D:$D,"TAC") | M31: =COUNTIF('Processos CETESB'!$A:$A,$A31) | N31: =COUNTIF(Incêndios!$A:$A,$A31) | O31: =COUNTIF(Licenciamentos!$A:$A,$A31) | P31: Não iniciado
A33: Campos em amarelo = preenchimento manual a partir da consulta oficial. Colunas J:O são contagens automáticas das abas de detalhe.

Sheet CAR
A1: Imóvel | B1: Município | C1: Matrícula | D1: Área da matrícula (ha) | E1: N° do CAR (recibo) | F1: Situação do CAR | G1: Data de inscrição | H1: Última retificação | I1: Área do imóvel no CAR (ha) | J1: Reserva Legal declarada (ha) | K1: RL averbada / compensada | L1: APP (ha) | M1: Área consolidada (ha) | N1: Passivo / área a recuperar (ha) | O1: Adesão ao PRA | P1: Sobreposições identificadas | Q1: Fonte / data da consulta | R1: Observações
A2: Fazenda Ipê | B2: Sto Antonio do Aracanguá | C2: 5787 | D2: 473.34
A3: Fazenda São Geraldo | B3: Colina | C3: 176 | D3: 467.06
A4: Fazenda São Geraldo | B4: Colina | C4: 19852 | D4: 26.62
A5: Fazenda São Geraldo | B5: Colina | C5: 14036 | D5: 40.6802
A6: Fazenda Conquista | B6: Santo Antonio do Aracanguá | C6: 73291 | D6: 239.0512
A7: Fazenda Conquista | B7: Santo Antonio do Aracanguá | C7: 696 | D7: 12.1
A8: Fazenda Conquista | B8: Santo Antonio do Aracanguá | C8: 41325 | D8: 12.1
A9: Fazenda Conquista | B9: Santo Antonio do Aracanguá | C9: 41326 | D9: 445.885
A10: Fazenda Conquista | B10: Santo Antonio do Aracanguá | C10: 41327 | D10: 427.6346
A11: Fazenda Santo Antonio | B11: Guapiaçu | C11: 38971 | D11: 2017.4781
A12: Fazenda Santo Antonio | B12: Guapiaçu | C12: 10632 | D12: 70.18
A13: Fazenda Alvorada | B13: Altair | C13: 7430 | D13: 584.914
... A55: Fazenda São Francisco (S.Pedro) GEO c/ desmembramento | B55: Guaraci | C55: 89692 | D55: 221.34
A56: FAZENDA CÓRREGO RICO - MFG-18000 | C56: 10328 - 14023
A57: FAZENDA QUATRO IRMÃOS - SOAs-18001 | C57: 9477
A58: FAZ. GIRASSOIS - GAQ-18002 | C58: 9481
A59: FAZ. MANGUE - MQ | C59: 10487
A60: FAZENDA AGUA DOCE PARTE IV - RJP | C60: 17035
A61: FAZENDA AGUA DOCE PARTE II - MAP | C61: 17033
A62: FAZENDA ANTONIO BIANCO - SBA | C62: 11391
A63: FAZ. SANTO INACIO - ILMJA | C63: 14022
A64: FAZENDA CÓRREGO RICO - LAN | C64: 14021
A65: FAZENDA OLIVEIRA - MAO | C65: 17864

Sheet Outorgas
A1: Imóvel | B1: Município | C1: Matrícula | D1: Tipo de uso | E1: Corpo hídrico / aquífero | F1: Órgão outorgante | G1: N° da portaria / resolução | H1: N° do processo | I1: Vazão outorgada (m³/h) | J1: Regime (h/dia — dias/mês) | K1: Volume anual (m³) | L1: Data de emissão | M1: Validade | N1: Situação | O1: Coordenadas do ponto | P1: UGRHI / bacia | Q1: Fonte / data da consulta | R1: Observações

Sheet Autos e TCRA
A1: Imóvel | B1: Município | C1: Matrícula | D1: Tipo de documento | E1: N° do documento | F1: Órgão | G1: Data | H1: Descrição da infração / objeto | I1: Enquadramento legal | J1: Valor da multa (R$) | K1: Situação | L1: TCRA / TAC vinculado | M1: Área a recuperar (ha) | N1: PRAD protocolado | O1: Prazo de execução | P1: Status de cumprimento | Q1: Fonte / data da consulta | R1: Observações

Sheet Processos CETESB
A1: Imóvel | B1: Município | C1: N° do processo CETESB | D1: Agência Ambiental | E1: Assunto / objeto | F1: Data de abertura | G1: Situação | H1: Última movimentação | I1: Exigências pendentes | J1: Prazo de atendimento | K1: Responsável técnico / ART | L1: Fonte / data da consulta | M1: Observações

Sheet Incêndios
A1: Imóvel | B1: Município | C1: Matrícula | D1: Data da ocorrência | E1: Área atingida (ha) | F1: Cobertura atingida | G1: Atingiu APP/Reserva Legal | H1: Origem provável | I1: Focos INPE (n°/data) | J1: Boletim de Ocorrência | K1: Houve autuação (n° do auto) | L1: Ação de recuperação adotada | M1: Custo / prejuízo estimado (R$) | N1: Fonte / data da consulta | O1: Observações

Sheet Licenciamentos
A1: Imóvel | B1: Município | C1: Matrícula | D1: Tipo de documento | E1: N° da licença / documento | F1: N° do processo | G1: Órgão emissor | H1: Objeto / atividade licenciada | I1: Data de emissão | J1: Validade | K1: Situação | L1: Prazo p/ renovação (120 dias antes) | M1: Condicionantes pendentes | N1: Responsável técnico / ART | O1: Fonte / data da consulta | P1: Observações
L2: =IF(J2="","",J2-120)
L3: =IF(J3="","",J3-120)
L4: =IF(J4="","",J4-120)
L5: =IF(J5="","",J5-120)
L6: =IF(J6="","",J6-120)
L7: =IF(J7="","",J7-120)
L8: =IF(J8="","",J8-120)
L9: =IF(J9="","",J9-120)
L10: =IF(J10="","",J10-120)
L11: =IF(J11="","",J11-120)
L12: =IF(J12="","",J12-120)
L13: =IF(J13="","",J13-120)
... L61: =IF(J61="","",J61-120)

Sheet Base - Próprias
B2: Imóvel | C2: Município | D2: CCIR | E2: Matrícula | F2: Área da Mat. (ha) | G2: Área Imóvel
B4: Fazenda Ipê | C4: Sto Antonio do Aracanguá | D4: 607.029.001.147-7 | E4: 5787 | F4: 473.34 | G4: 473.34
B5: Fazenda São Geraldo | C5: Colina | D5: 604.020.000.698-8 | E5: 176 | F5: 467.06 | G5: 534.3602
E6: 19852 | F6: 26.62
E7: 14036 | F7: 40.6802
B8: Fazenda Conquista | C8: Santo Antonio do Aracanguá | D8: 607.029.011.673-2 | E8: 73291 | F8: 239.0512 | G8: 1136.7708
E9: 696 | F9: 12.1
E10: 41325 | F10: 12.1
E11: 41326 | F11: 445.885
E12: 41327 | F12: 427.6346
B13: Fazenda Santo Antonio | C13: Guapiaçu | D13: 610.046.259.063-2 | E13: 38971 | F13: 2017.4781 | G13: 2087.6581
E14: 10632 | F14: 70.18
B15: Fazenda Alvorada | C15: Altair | D15: 603.015.001.104-1 | E15: 7430 | F15: 584.914 | G15: 679.2288
E16: 44121 | F16: 20.7091
E17: 44122 | F17: 26.2366
E18: 44123 | F18: 18.7245
E19: 44124 | F19: 28.6446
B20: Fazenda Santa Inacia | C20: Colina | D20: 604.020.001.457-3 | E20: 14892 | F20: 522.5 | G20: 522.5
B21: Fazenda Iracema | C21: Colina | D21: 604.020.001.449-2 | E21: 10319 | F21: 550.99 | G21: 550.99
B22: Fazenda Vitória | C22: Santo Antonio do Aracanguá | D22: 999.989.600.148-5 | E22: 45933 | F22: 10.18 | G22: 386.0636
E23: 45932 | F23: 123.778
E24: 49159 | F24: 94.8056
E25: 3201 | F25: 157.3
B26: Fazenda Santa Helena | C26: Santo Antonio do Aracanguá | D26: 617.016.010.375-7 | E26: 37883 | F26: 295.7632 | G26: 338.8
E27: 37882 | F27: 43.0368
B28: Fazenda São José | C28: Severínia | D28: 611.131.001.260-0 | E28: 7207 | F28: 519.332 | G28: 519.332
B29: Fazenda São Luiz | C29: Severínia | D29: 611.131.000.710-0 | E29: 24047 | F29: 57.5718 | G29: 612.0772
E30: 30714 | F30: 20.656
E31: 12236 | F31: 271.645
E32: 12237 | F32: 245.7994
E33: 6710 | F33: 9.255
E34: 24932 | F34: 7.15
B35: Sítio São José I | C35: Severínia | D35: 611.131.000.612-0 | E35: 417 | F35: 16.94 | G35: 16.94
B36: Fazenda Santa Rosa | C36: Altair | D36: 636.061.049.859-9 | E36: 18300 | F36: 1285.0442 | G36: 1285.0442
B37: Fazenda Santa Cruz | C37: Onda Verde | D37: 610.119.000.620-7 | E37: 1469 | F37: 91.96 | G37: 91.96
B38: Fazenda Santa Maria | C38: Monte Azul Paulista | D38: 612.073.001.678-3 | E38: 119 | F38: 341.22 | G38: 341.22
B39: Fazenda São João | C39: Guaraci | D39: 999.954.021.474-3 | E39: 45390 | F39: 32.052 | G39: 1813.887
E40: 28886 | F40: 13.9616
E41: 28885 | F41: 1767.8734
B42: Fazenda Primavera | C42: Santo Antonio do Aracanguá | D42: 617.016.010.383-8 | E42: 31031 | F42: 1908.4 | G42: 2162.5182
...

Sheet Base - Parceiras
A1: Fazenda | B1: Matrícula | C1: INCRA | D1: ITR
A2: FAZENDA CÓRREGO RICO - MFG-18000 | B2: 10328 - 14023 | C2: 603.015.272.353-7 | D2: 3.413.635-5
A3: FAZENDA QUATRO IRMÃOS - SOAs-18001 | B3: 9477 | C3: 000.019.292.982-2 | D3: 0.784.839-0
D4: 0.784.839-0
D5: 6.134.436-2
A6: FAZ. GIRASSOIS - GAQ-18002 | B6: 9481 | C6: 000.019.292.966-0 | D6: 6.134.436-2
D7: 0.323.933-0
D8: 7.349.298-1
D9: 0.327.778-0
D10: 3.694.372-0
A11: FAZ. MANGUE - MQ | B11: 10487 | C11: 603.031.273.058-6 | D11: 6.134.432-0
D12: 6.134.432-0
A13: FAZ. MANGUE - MQ | B13: 10487 | C13: 603.031.273.058-6 | D13: 6.134.432-0
D14: 3.101.001-6
D15: 3.101.001-6
D16: 3.101.001-6
D17: 0.312.930-6
A18: FAZENDA AGUA DOCE PARTE IV - RJP | B18: 17035 | C18: 603.031.000.400-4 | D18: 0.312.930-6
A19: FAZENDA AGUA DOCE PARTE II - MAP | B19: 17033 | C19: 999.989.956.007-8 | D19: 8.876.740-0
A20: FAZENDA ANTONIO BIANCO - SBA | B20: 11391 | C20: 603.031.273.066-7 | D20: 3.101.001-6
D21: 3.101.001-6
D22: 3.101.001-6
D23: 3.101.001-6
A24: FAZ. SANTO INACIO - ILMJA | B24: 14022 | C24: 950.122.860.476-5 | D24: 0.327.777-1
A25: FAZ. SANTO INACIO - ILMJA | B25: 14022 | C25: 950.122.860.476-5 | D25: 0.327.777-1
D26: 3.694.372-0
D27: 3.262.606-1
A28: FAZENDA CÓRREGO RICO - LAN | B28: 14021 | C28: 623.024.006.955-2 | D28: 0.290.263-0
D29: 3.262.606-1
D30: 3.262.606-1
D31: 6.134.435-4
D32: 0.308.653-4
A33: FAZENDA OLIVEIRA - MAO | B33: 17864 | C33: 603.031.000.507-8 | D33: 0.322.197-0
D34: 0.300.029-0

Sheet Listas
A1: lista_1 | B1: lista_2 | C1: lista_3 | D1: lista_4 | E1: lista_5 | F1: lista_6 | G1: lista_7 | H1: lista_8 | I1: lista_9 | J1: lista_10 | K1: lista_11 | L1: lista_12 | M1: lista_13 | N1: lista_14 | O1: lista_15 | P1: lista_16 | Q1: lista_17 | R1: lista_18 | S1: lista_19 | T1: lista_20 | U1: lista_21 | V1: lista_22
A2: Ativo | B2: Não iniciado | C2: Ativo | D2: Sim | E2: Sim | F2: Fazenda Ipê | G2: Captação superficial | H2: DAEE-SP | I2: Vigente | J2: Auto de Infração Ambiental (AIA) | K2: CETESB | L2: Em defesa | M2: Sim | N2: Não iniciado | O2: Em análise | P2: Cana-de-açúcar | Q2: Sim — APP | R2: Acidental | S2: Sim | T2: Licença Prévia (LP) | U2: CETESB | V2: Vigente
A3: Pendente | B3: Em consulta | C3: Pendente | D3: Não | E3: Não | F3: Fazenda São Geraldo | G3: Poço tubular profundo | H3: ANA | I3: Vencida | J3: Auto de Imposição de Penalidade | K3: Polícia Militar Ambiental | L3: Em recurso | M3: Não | N3: Em execução | O3: Em exigência | P3: Pastagem | Q3: Sim — Reserva Legal | R3: Criminosa/dolosa | S3: Não | T3: Licença de Instalação (LI) | U3: SEMIL-SP | V3: Vencida
A4: Em análise | B4: Concluído | C4: Em análise | D4: Em processo | E4: Não se aplica | F4: Fazenda Conquista | G4: Poço raso/cacimba | H4: Município | I4: Em renovação | J4: Auto de Inspeção | K4: IBAMA | L4: Aguardando julgamento | M4: Em elaboração | N4: Concluído | O4: Deferido | P4: Reflorestamento | Q4: Sim — ambos | R4: Origem externa (vizinho/rodovia/ferrovia) | S4: A verificar | T4: Licença de Operação (LO) | U4: IBAMA | V4: Em renovação
A5: Cancelado | B5: Pendência documental | C5: Analisado sem pendências | D5: Não se aplica | E5: A verificar | F5: Fazenda Santo Antonio | G5: Barramento/reservatório | H5: Outro | I5: Em análise | J5: TCRA | K5: SEMIL-SP | L5: Pago | M5: Não se aplica | N5: Em atraso | O5: Indeferido | P5: Fragmento nativo | Q5: Não | R5: Rede elétrica | T5: Licença Ambiental Simplificada | U5: Prefeitura | V5: Em análise
A6: Suspenso | B6: Não se aplica | C6: Cancelado | F6: Fazenda Alvorada | G6: Travessia | I6: Cancelada | J6: TAC | K6: Ministério Público | L6: Parcelado | N6: Não se aplica | O6: Arquivado | P6: APP | Q6: A verificar | R6: Balão | T6: Renovação de LO | U6: DAEE | V6: Cancelada
A7: Não inscrito | C7: Suspenso | F7: Fazenda Santa Inacia | G7: Lançamento de efluente | I7: Não possui | J7: Embargo | K7: Prefeitura | L7: Convertido em serviços | O7: Suspenso | P7: Reserva Legal | R7: Queima controlada autorizada | T7: CADRI | U7: Outro | V7: Não se aplica
A8: A verificar | C8: Não inscrito | F8: Fazenda Iracema | G8: Dispensa de outorga | I8: A verificar | J8: Notificação | K8: Outro | L8: Anulado | O8: Recurso | P8: Aceiro/carreador | R8: Desconhecida | T8: Certificado de Dispensa de Licença | V8: A verificar
F9: Fazenda Vitória | G9: Uso insignificante | L9: Inscrito em dívida ativa | P9: Misto | T9: Autorização de supressão de vegetação
F10: Fazenda Santa Helena | L10: Encerrado | T10: Autorização de intervenção em APP
F11: Fazenda São José | T11: Licença de queima controlada
F12: Fazenda São Luiz | T12: Cadastro de fonte de poluição
F13: Sítio São José I
F14: Fazenda Santa Rosa
F15: Fazenda Santa Cruz
F16: Fazenda Santa Maria
F17: Fazenda São João
F18: Fazenda Primavera
F19: Fazenda São Pedro
F20: Fazenda Lago Azul
F21: Fazenda São Francisco (S.Pedro) GEO c/ desmembramento
F22: FAZENDA CÓRREGO RICO - MFG-18000
F23: FAZENDA QUATRO IRMÃOS - SOAs-18001
F24: FAZ. GIRASSOIS - GAQ-18002
... F31: FAZENDA OLIVEIRA - MAO
